Traceback (most recent call last):
  File "/home/mkzia/anaconda3/lib/python3.9/site-packages/jupyter_cache/executors/utils.py", line 51, in single_nb_execution
    executenb(
  File "/home/mkzia/anaconda3/lib/python3.9/site-packages/nbclient/client.py", line 1112, in execute
    return NotebookClient(nb=nb, resources=resources, km=km, **kwargs).execute()
  File "/home/mkzia/anaconda3/lib/python3.9/site-packages/nbclient/util.py", line 74, in wrapped
    return just_run(coro(*args, **kwargs))
  File "/home/mkzia/anaconda3/lib/python3.9/site-packages/nbclient/util.py", line 53, in just_run
    return loop.run_until_complete(coro)
  File "/home/mkzia/anaconda3/lib/python3.9/asyncio/base_events.py", line 642, in run_until_complete
    return future.result()
  File "/home/mkzia/anaconda3/lib/python3.9/site-packages/nbclient/client.py", line 553, in async_execute
    await self.async_execute_cell(
  File "/home/mkzia/anaconda3/lib/python3.9/site-packages/nbclient/client.py", line 857, in async_execute_cell
    self._check_raise_for_error(cell, exec_reply)
  File "/home/mkzia/anaconda3/lib/python3.9/site-packages/nbclient/client.py", line 760, in _check_raise_for_error
    raise CellExecutionError.from_cell_and_msg(cell, exec_reply_content)
nbclient.exceptions.CellExecutionError: An error occurred while executing the following cell:
------------------
import sqlite3
import pandas as pd

conn = sqlite3.connect('100_patients.db')

sql_statement = """
SELECT
    *
FROM
    PatientCorePopulatedTable
LIMIT
    10;
"""
df = pd.read_sql_query(sql_statement, conn).set_table_attributes('style="font-size: 10px"')
display(df)  
------------------

[0;31m---------------------------------------------------------------------------[0m
[0;31mAttributeError[0m                            Traceback (most recent call last)
[0;32m/tmp/ipykernel_1511/1813420826.py[0m in [0;36m<module>[0;34m[0m
[1;32m     12[0m     [0;36m10[0m[0;34m;[0m[0;34m[0m[0;34m[0m[0m
[1;32m     13[0m """
[0;32m---> 14[0;31m [0mdf[0m [0;34m=[0m [0mpd[0m[0;34m.[0m[0mread_sql_query[0m[0;34m([0m[0msql_statement[0m[0;34m,[0m [0mconn[0m[0;34m)[0m[0;34m.[0m[0mset_table_attributes[0m[0;34m([0m[0;34m'style="font-size: 10px"'[0m[0;34m)[0m[0;34m[0m[0;34m[0m[0m
[0m[1;32m     15[0m [0mdisplay[0m[0;34m([0m[0mdf[0m[0;34m)[0m[0;34m[0m[0;34m[0m[0m

[0;32m~/anaconda3/lib/python3.9/site-packages/pandas/core/generic.py[0m in [0;36m__getattr__[0;34m(self, name)[0m
[1;32m   5485[0m         ):
[1;32m   5486[0m             [0;32mreturn[0m [0mself[0m[0;34m[[0m[0mname[0m[0;34m][0m[0;34m[0m[0;34m[0m[0m
[0;32m-> 5487[0;31m         [0;32mreturn[0m [0mobject[0m[0;34m.[0m[0m__getattribute__[0m[0;34m([0m[0mself[0m[0;34m,[0m [0mname[0m[0;34m)[0m[0;34m[0m[0;34m[0m[0m
[0m[1;32m   5488[0m [0;34m[0m[0m
[1;32m   5489[0m     [0;32mdef[0m [0m__setattr__[0m[0;34m([0m[0mself[0m[0;34m,[0m [0mname[0m[0;34m:[0m [0mstr[0m[0;34m,[0m [0mvalue[0m[0;34m)[0m [0;34m->[0m [0;32mNone[0m[0;34m:[0m[0;34m[0m[0;34m[0m[0m

[0;31mAttributeError[0m: 'DataFrame' object has no attribute 'set_table_attributes'
AttributeError: 'DataFrame' object has no attribute 'set_table_attributes'

